<?xml version="1.0" encoding="UTF-8"?>
<testng-results retried="2" ignored="0" total="5" passed="1" failed="2" skipped="0">
  <reporter-output>
  </reporter-output>
  <suite started-at="2019-03-22T12:41:21 GET" name="Suite1" finished-at="2019-03-22T12:41:31 GET" duration-ms="10237">
    <groups>
    </groups>
    <test started-at="2019-03-22T12:41:21 GET" name="TestCase_1" finished-at="2019-03-22T12:41:31 GET" duration-ms="10237">
      <class name="testNgTesting">
        <test-method is-config="true" signature="setup()[pri:0, instance:testNgTesting@7880cdf3]" started-at="2019-03-22T12:41:21 GET" name="setup" finished-at="2019-03-22T12:41:21 GET" duration-ms="24" status="PASS">
          <reporter-output>
          </reporter-output>
        </test-method> <!-- setup -->
        <test-method retried="true" signature="Test1()[pri:0, instance:testNgTesting@7880cdf3]" started-at="2019-03-22T12:41:21 GET" name="Test1" finished-at="2019-03-22T12:41:26 GET" duration-ms="5031" status="SKIP">
          <exception class="java.lang.AssertionError">
            <message>
              <![CDATA[expected [1] but found [2]]]>
            </message>
            <full-stacktrace>
              <![CDATA[java.lang.AssertionError: expected [1] but found [2]
at org.testng.Assert.fail(Assert.java:97)
at org.testng.Assert.assertEqualsImpl(Assert.java:136)
at org.testng.Assert.assertEquals(Assert.java:118)
at org.testng.Assert.assertEquals(Assert.java:839)
at org.testng.Assert.assertEquals(Assert.java:849)
at testNgTesting.Test1(testNgTesting.java:29)
at java.base/jdk.internal.reflect.NativeMethodAccessorImpl.invoke0(Native Method)
at java.base/jdk.internal.reflect.NativeMethodAccessorImpl.invoke(NativeMethodAccessorImpl.java:62)
at java.base/jdk.internal.reflect.DelegatingMethodAccessorImpl.invoke(DelegatingMethodAccessorImpl.java:43)
at java.base/java.lang.reflect.Method.invoke(Method.java:566)
at org.testng.internal.MethodInvocationHelper.invokeMethod(MethodInvocationHelper.java:131)
at org.testng.internal.TestInvoker.invokeMethod(TestInvoker.java:570)
at org.testng.internal.TestInvoker.invokeTestMethod(TestInvoker.java:170)
at org.testng.internal.MethodRunner.runInSequence(MethodRunner.java:46)
at org.testng.internal.TestInvoker$MethodInvocationAgent.invoke(TestInvoker.java:790)
at org.testng.internal.TestInvoker.invokeTestMethods(TestInvoker.java:143)
at org.testng.internal.TestMethodWorker.invokeTestMethods(TestMethodWorker.java:146)
at org.testng.internal.TestMethodWorker.run(TestMethodWorker.java:128)
at org.testng.TestRunner.privateRun(TestRunner.java:763)
at org.testng.TestRunner.run(TestRunner.java:594)
at org.testng.SuiteRunner.runTest(SuiteRunner.java:398)
at org.testng.SuiteRunner.access$000(SuiteRunner.java:41)
at org.testng.SuiteRunner$SuiteWorker.run(SuiteRunner.java:437)
at org.testng.internal.thread.ThreadUtil.lambda$execute$0(ThreadUtil.java:67)
at java.base/java.util.concurrent.FutureTask.run(FutureTask.java:264)
at java.base/java.util.concurrent.ThreadPoolExecutor.runWorker(ThreadPoolExecutor.java:1128)
at java.base/java.util.concurrent.ThreadPoolExecutor$Worker.run(ThreadPoolExecutor.java:628)
at java.base/java.lang.Thread.run(Thread.java:834)
]]>
            </full-stacktrace>
          </exception> <!-- java.lang.AssertionError -->
          <reporter-output>
          </reporter-output>
        </test-method> <!-- Test1 -->
        <test-method signature="Test1()[pri:0, instance:testNgTesting@7880cdf3]" started-at="2019-03-22T12:41:26 GET" name="Test1" finished-at="2019-03-22T12:41:31 GET" duration-ms="5001" status="FAIL">
          <exception class="java.lang.AssertionError">
            <message>
              <![CDATA[expected [1] but found [2]]]>
            </message>
            <full-stacktrace>
              <![CDATA[java.lang.AssertionError: expected [1] but found [2]
at org.testng.Assert.fail(Assert.java:97)
at org.testng.Assert.assertEqualsImpl(Assert.java:136)
at org.testng.Assert.assertEquals(Assert.java:118)
at org.testng.Assert.assertEquals(Assert.java:839)
at org.testng.Assert.assertEquals(Assert.java:849)
at testNgTesting.Test1(testNgTesting.java:29)
at java.base/jdk.internal.reflect.NativeMethodAccessorImpl.invoke0(Native Method)
at java.base/jdk.internal.reflect.NativeMethodAccessorImpl.invoke(NativeMethodAccessorImpl.java:62)
at java.base/jdk.internal.reflect.DelegatingMethodAccessorImpl.invoke(DelegatingMethodAccessorImpl.java:43)
at java.base/java.lang.reflect.Method.invoke(Method.java:566)
at org.testng.internal.MethodInvocationHelper.invokeMethod(MethodInvocationHelper.java:131)
at org.testng.internal.TestInvoker.invokeMethod(TestInvoker.java:570)
at org.testng.internal.TestInvoker.retryFailed(TestInvoker.java:201)
at org.testng.internal.MethodRunner.runInSequence(MethodRunner.java:58)
at org.testng.internal.TestInvoker$MethodInvocationAgent.invoke(TestInvoker.java:790)
at org.testng.internal.TestInvoker.invokeTestMethods(TestInvoker.java:143)
at org.testng.internal.TestMethodWorker.invokeTestMethods(TestMethodWorker.java:146)
at org.testng.internal.TestMethodWorker.run(TestMethodWorker.java:128)
at org.testng.TestRunner.privateRun(TestRunner.java:763)
at org.testng.TestRunner.run(TestRunner.java:594)
at org.testng.SuiteRunner.runTest(SuiteRunner.java:398)
at org.testng.SuiteRunner.access$000(SuiteRunner.java:41)
at org.testng.SuiteRunner$SuiteWorker.run(SuiteRunner.java:437)
at org.testng.internal.thread.ThreadUtil.lambda$execute$0(ThreadUtil.java:67)
at java.base/java.util.concurrent.FutureTask.run(FutureTask.java:264)
at java.base/java.util.concurrent.ThreadPoolExecutor.runWorker(ThreadPoolExecutor.java:1128)
at java.base/java.util.concurrent.ThreadPoolExecutor$Worker.run(ThreadPoolExecutor.java:628)
at java.base/java.lang.Thread.run(Thread.java:834)
]]>
            </full-stacktrace>
          </exception> <!-- java.lang.AssertionError -->
          <reporter-output>
          </reporter-output>
        </test-method> <!-- Test1 -->
        <test-method retried="true" signature="Test2()[pri:0, instance:testNgTesting@7880cdf3]" started-at="2019-03-22T12:41:31 GET" name="Test2" finished-at="2019-03-22T12:41:31 GET" duration-ms="0" status="SKIP">
          <exception class="java.lang.AssertionError">
            <message>
              <![CDATA[expected [2] but found [1]]]>
            </message>
            <full-stacktrace>
              <![CDATA[java.lang.AssertionError: expected [2] but found [1]
at org.testng.Assert.fail(Assert.java:97)
at org.testng.Assert.assertEqualsImpl(Assert.java:136)
at org.testng.Assert.assertEquals(Assert.java:118)
at org.testng.Assert.assertEquals(Assert.java:839)
at org.testng.Assert.assertEquals(Assert.java:849)
at testNgTesting.Test2(testNgTesting.java:38)
at java.base/jdk.internal.reflect.NativeMethodAccessorImpl.invoke0(Native Method)
at java.base/jdk.internal.reflect.NativeMethodAccessorImpl.invoke(NativeMethodAccessorImpl.java:62)
at java.base/jdk.internal.reflect.DelegatingMethodAccessorImpl.invoke(DelegatingMethodAccessorImpl.java:43)
at java.base/java.lang.reflect.Method.invoke(Method.java:566)
at org.testng.internal.MethodInvocationHelper.invokeMethod(MethodInvocationHelper.java:131)
at org.testng.internal.TestInvoker.invokeMethod(TestInvoker.java:570)
at org.testng.internal.TestInvoker.invokeTestMethod(TestInvoker.java:170)
at org.testng.internal.MethodRunner.runInSequence(MethodRunner.java:46)
at org.testng.internal.TestInvoker$MethodInvocationAgent.invoke(TestInvoker.java:790)
at org.testng.internal.TestInvoker.invokeTestMethods(TestInvoker.java:143)
at org.testng.internal.TestMethodWorker.invokeTestMethods(TestMethodWorker.java:146)
at org.testng.internal.TestMethodWorker.run(TestMethodWorker.java:128)
at org.testng.TestRunner.privateRun(TestRunner.java:763)
at org.testng.TestRunner.run(TestRunner.java:594)
at org.testng.SuiteRunner.runTest(SuiteRunner.java:398)
at org.testng.SuiteRunner.access$000(SuiteRunner.java:41)
at org.testng.SuiteRunner$SuiteWorker.run(SuiteRunner.java:437)
at org.testng.internal.thread.ThreadUtil.lambda$execute$0(ThreadUtil.java:67)
at java.base/java.util.concurrent.FutureTask.run(FutureTask.java:264)
at java.base/java.util.concurrent.ThreadPoolExecutor.runWorker(ThreadPoolExecutor.java:1128)
at java.base/java.util.concurrent.ThreadPoolExecutor$Worker.run(ThreadPoolExecutor.java:628)
at java.base/java.lang.Thread.run(Thread.java:834)
]]>
            </full-stacktrace>
          </exception> <!-- java.lang.AssertionError -->
          <reporter-output>
          </reporter-output>
        </test-method> <!-- Test2 -->
        <test-method signature="Test2()[pri:0, instance:testNgTesting@7880cdf3]" started-at="2019-03-22T12:41:31 GET" name="Test2" finished-at="2019-03-22T12:41:31 GET" duration-ms="0" status="FAIL">
          <exception class="java.lang.AssertionError">
            <message>
              <![CDATA[expected [2] but found [1]]]>
            </message>
            <full-stacktrace>
              <![CDATA[java.lang.AssertionError: expected [2] but found [1]
at org.testng.Assert.fail(Assert.java:97)
at org.testng.Assert.assertEqualsImpl(Assert.java:136)
at org.testng.Assert.assertEquals(Assert.java:118)
at org.testng.Assert.assertEquals(Assert.java:839)
at org.testng.Assert.assertEquals(Assert.java:849)
at testNgTesting.Test2(testNgTesting.java:38)
at java.base/jdk.internal.reflect.NativeMethodAccessorImpl.invoke0(Native Method)
at java.base/jdk.internal.reflect.NativeMethodAccessorImpl.invoke(NativeMethodAccessorImpl.java:62)
at java.base/jdk.internal.reflect.DelegatingMethodAccessorImpl.invoke(DelegatingMethodAccessorImpl.java:43)
at java.base/java.lang.reflect.Method.invoke(Method.java:566)
at org.testng.internal.MethodInvocationHelper.invokeMethod(MethodInvocationHelper.java:131)
at org.testng.internal.TestInvoker.invokeMethod(TestInvoker.java:570)
at org.testng.internal.TestInvoker.retryFailed(TestInvoker.java:201)
at org.testng.internal.MethodRunner.runInSequence(MethodRunner.java:58)
at org.testng.internal.TestInvoker$MethodInvocationAgent.invoke(TestInvoker.java:790)
at org.testng.internal.TestInvoker.invokeTestMethods(TestInvoker.java:143)
at org.testng.internal.TestMethodWorker.invokeTestMethods(TestMethodWorker.java:146)
at org.testng.internal.TestMethodWorker.run(TestMethodWorker.java:128)
at org.testng.TestRunner.privateRun(TestRunner.java:763)
at org.testng.TestRunner.run(TestRunner.java:594)
at org.testng.SuiteRunner.runTest(SuiteRunner.java:398)
at org.testng.SuiteRunner.access$000(SuiteRunner.java:41)
at org.testng.SuiteRunner$SuiteWorker.run(SuiteRunner.java:437)
at org.testng.internal.thread.ThreadUtil.lambda$execute$0(ThreadUtil.java:67)
at java.base/java.util.concurrent.FutureTask.run(FutureTask.java:264)
at java.base/java.util.concurrent.ThreadPoolExecutor.runWorker(ThreadPoolExecutor.java:1128)
at java.base/java.util.concurrent.ThreadPoolExecutor$Worker.run(ThreadPoolExecutor.java:628)
at java.base/java.lang.Thread.run(Thread.java:834)
]]>
            </full-stacktrace>
          </exception> <!-- java.lang.AssertionError -->
          <reporter-output>
          </reporter-output>
        </test-method> <!-- Test2 -->
        <test-method signature="Test3()[pri:0, instance:testNgTesting@7880cdf3]" started-at="2019-03-22T12:41:31 GET" name="Test3" finished-at="2019-03-22T12:41:31 GET" duration-ms="1" status="PASS">
          <reporter-output>
          </reporter-output>
        </test-method> <!-- Test3 -->
      </class> <!-- testNgTesting -->
    </test> <!-- TestCase_1 -->
  </suite> <!-- Suite1 -->
</testng-results>
